Workbook

Sheet DASHBOARD
A1: ⚙ CONTROL DE CURSADO E INGRESOS · ÁREA INGENIERÍA · Q4 2026
A2: Última actualización: Abril 2026
B4: ENERO | D4: FEBRERO | H4: MARZO | J4: ABRIL
B5: META | D5: META | H5: META | J5: META
B6: ='CURSADO-INGRESADO Q4'!H58 -> 19300000 | D6: ='CURSADO-INGRESADO Q4'!K58 -> 11438356 | H6: ='CURSADO-INGRESADO Q4'!N58 -> 8946267 | J6: 0
B7: FACTURADO | D7: FACTURADO | H7: FACTURADO | J7: FACTURADO
B8: ='CURSADO-INGRESADO Q4'!H60 -> 24729067 | D8: ='CURSADO-INGRESADO Q4'!K60 -> 11438356 | H8: ='CURSADO-INGRESADO Q4'!N60 -> 8946267 | J8: ='CURSADO-INGRESADO Q4'!Q60 -> 38644475
B9: INGRESO | D9: INGRESO | H9: INGRESO | J9: INGRESO
B10: ='CURSADO-INGRESADO Q4'!H59 -> 14504626 | D10: ='CURSADO-INGRESADO Q4'!K59 -> 10356731 | H10: ='CURSADO-INGRESADO Q4'!N59 -> 8695342 | J10: ='CURSADO-INGRESADO Q4'!Q59 -> 30554311
B11: =IF(B6>0,B8/B6,0) -> 1.2812988 | D11: =IF(D6>0,D8/D6,0) -> 1 | H11: =IF(H6>0,H8/H6,0) -> 1 | J11: =IF(J6>0,J8/J6,0) -> 0
B13: RESUMEN ACUMULADO Q4
C14: META FACTURADA | D14: FACTURADO REAL | E14: INGRESO CAJA | F14: EFICIENCIA | H14: CUENTAS X COBRAR | I14: MONTO
B15: Enero | C15: ='CURSADO-INGRESADO Q4'!H58 -> 19300000 | D15: ='CURSADO-INGRESADO Q4'!H60 -> 24729067 | E15: ='CURSADO-INGRESADO Q4'!H59 -> 14504626 | F15: =IF(C15>0,D15/C15,0) -> 1.2812988 | H15: No Facturado (público) | I15: ='CURSADO-INGRESADO Q4'!B29 -> 0
B16: Febrero | C16: ='CURSADO-INGRESADO Q4'!K58 -> 11438356 | D16: ='CURSADO-INGRESADO Q4'!K60 -> 11438356 | E16: ='CURSADO-INGRESADO Q4'!K59 -> 10356731 | F16: =IF(C16>0,D16/C16,0) -> 1 | H16: Facturado / No Cobrado | I16: ='CURSADO-INGRESADO Q4'!E29 -> 0
B17: Marzo | C17: ='CURSADO-INGRESADO Q4'!N58 -> 8946267 | D17: ='CURSADO-INGRESADO Q4'!N60 -> 8946267 | E17: ='CURSADO-INGRESADO Q4'!N59 -> 8695342 | F17: =IF(C17>0,D17/C17,0) -> 1 | H17: Boletas por Cursar | I17: ='CURSADO-INGRESADO Q4'!E48 -> 0
B18: Abril | C18: =+'CURSADO-INGRESADO Q4'!Q30 -> 38644475 | D18: ='CURSADO-INGRESADO Q4'!Q60 -> 38644475 | E18: ='CURSADO-INGRESADO Q4'!Q59 -> 30554311 | F18: =IF(C18>0,D18/C18,0) -> 1 | H18: Prox. a Facturar | I18: ='CURSADO-INGRESADO Q4'!E41 -> 0
B19: TOTAL Q4 | C19: =SUM(C15:C18) -> 78329098 | D19: =SUM(D15:D18) -> 83758165 | E19: =SUM(E15:E18) -> 64111010 | F19: =IF(C19>0,D19/C19,0) -> 1.069311

Sheet CURSADO-INGRESADO Q4
A1: PÚBLICOS PENDIENTES A FACTURAR | D1: PRIVADOS PENDIENTES A FACTURAR | G1: FACTURADO ENERO 2026 | J1: FACTURADO FEBRERO 2026 | M1: FACTURADO MARZO 2026 | P1: FACTURADO ABRIL 2026 | S1: FACTURADO MAYO 2026
A2: PROYECTO | B2: MONTO A RECIBIR | D2: PROYECTO | E2: MONTO A RECIBIR | G2: PROYECTO | H2: MONTO CURSADO | J2: PROYECTO | K2: MONTO CURSADO | M2: PROYECTO | N2: MONTO CURSADO | P2: PROYECTO | Q2: MONTO CURSADO | S2: PROYECTO | T2: MONTO CURSADO
A3: 007. EP N°3 Diego de Almagro | B3: 7119000 | D3: 189. Monografías Ruta 5EP N°3 - Sub Sector B | E3: 1500000 | G3: 149. EP N°3 Plaza de Armas SFD | H3: 563575 | J3: 224. EP N°2 Ciclovia Colina | K3: 2382300 | M3: 223. EP N°2 Smapa Maipú | N3: 1700000 | P3: 076. EP Final Quillota | Q3: 11995200 | S3: 212. EP N°2 Machalí ( 50% Ingreso SERVIU) | T3: 20517358
A4: 010. EP N°2 Villa Paraíso | B4: 5391959 | D4: 189. Monografías Ruta 5EP N°3 - Sub Sector C | E4: 2250000 | G4: 182. EP N°3 UV 25 Conchalí | H4: 357768 | J4: 223. EP N°1 Smapa Maipú | K4: 1900000 | M4: 222. EP N°2 Veredas Talagante | N4: =3780000*0.4 -> 1512000 | P4: 222. EP N°3 Veredas Talagante | Q4: 756000 | S4: 206. EP N°3 Aprobación Lago Ranco | T4: 1697850
A5: 010. EP N°3 Villa Paraíso | B5: 1078392 | D5: 189. Monografías Ruta 5EP N°3 - Sub Sector D | E5: 4875000 | G5: 090. EP N°2 Valenzuela Puelma LRN | H5: 2600000 | J5: 946. EPN° 3 Veredas 18 Septiembre SFD | K5: 1079200 | M5: 090. EP N°2 Ema Valderrama , LRN | N5: 1300000 | P5: 225. EP N°2 El Zorro Lo Barnechea | Q5: 2589711 | S5: 227. EP N°3 Vuelo Dron | T5: 1115310
A6: 045. EP N°4 San Fernando | B6: 3148600 | D6: 189. Monografías Ruta 5EP N°3 - Sub Sector E | E6: 5421187 | G6: 098. EP N°2 Parque Tobalaba LRN | H6: 7450000 | J6: 225. EP N°1 El Zorro Lo Barnechea | K6: 2064182 | M6: 191. EP N°3 Loteo Alvaro Casanova, PÑL | N6: 2271300 | P6: 069. EP N°5 G8 y G10, San Antonio | Q6: 5093043 | S6: 229. EP N°1 Bodega La Cisterna | T6: 3137690
A7: 063. EP N°3 Osorno saldo restante | B7: 8248212 | D7: 204. EP N°2 Acceso Pichilemu Ingreso MOP | E7: 1265472 | G7: 188. EP N°2 Sendas 7 y 8 Lo Barnechea | H7: 4279875 | J7: 211. EP N°2 Adicional Holdco | K7: 357239 | M7: 191. EP N°3 Señalización Loteo A.Casanova, PÑL | N7: 1525500 | P7: 226. EP N°1 IMIV Intermedio CV Trading | Q7: 3187338 | S7: 224. EP N°3 Ciclovia Colina, CREAR | T7: 604608
A8: 069. EP San Antonio Saldo restante | B8: 16412966 | D8: 204. EP N°3 Aprobación Pichilemu MOP | E8: 632736 | G8: 210. EP N°1 Triángulo El Tabo | H8: 3250063 | J8: 211. EP N°2 Holdco | K8: 2143435 | M8: 203. EP N°3 IMIV Melipilla | N8: 637467 | P8: 205. EP N°2 Ingreso MOP, Quisco | Q8: 4140063 | S8: 161. EP N°3 Loteo Pabellón, DAL | T8: 1048862
A9: 093. EP N°3 Peumo | B9: 29550000 | D9: 205. EP N°3 Aprobación El Quisco MOP, SERVIU | E9: 818602 | G9: 210. EP N°2 Triángulo El Tabo | H9: 3250062 | J9: 222. EP N°1 Veredas Ochagavia Talagante | K9: =3780000*0.4 -> 1512000 | P9: 221. EP N°1 La Pintana | Q9: 6796000
A10: 210. EP N°3 Aprobación El Triángulo | B10: 6500125 | D10: 206. EP N°3 Aprobación Lago Ranco | E10: 1649315 | G10: 224. EP N°1 Ciclovia Colina | H10: 2382056 | P10: 228. EP N°1 Anticipo ext. | Q10: 601404
A11: 212. EP N°3 Machali | B11: 23936918 | D11: 208. EP N°3 Aprobación Tierra Amarilla | E11: 1660932 | G11: 219. EPN° 2 Taller inofensivo | H11: 595668 | P11: 228. EP N°1 Anticipo int. | Q11: 1303042
A12: 212. EP N°4 Machali | B12: 10258679 | D12: 209. EP N°2 Mitigaciones Electricas Maipu | E12: 1581840 | P12: 227. EP N°1 y 2 Vuelo Dron | Q12: 2071290
A13: 215. EP N°1 DS N°50 | B13: 14322920 | D13: 211. EP N°3 Holdco Aprobación | E13: 1067742 | Q13: =93600*1.19 -> 111384
A14: 215. EP N°2 DS N°50 | B14: 23871532 | D14: 218. EP N°3 Aceras Pedro Prado , la Pintana | E14: 474552
A15: 215. EP N°3 DS N°50 | B15: 33420145 | D15: 224. EP N°3 Ciclovia Colina | E15: 595514
A16: 215. EP N°4 DS N°50 | B16: 23871532 | D16: 224. EP N°4 Ciclovia Colina | E16: 595514
A17: 221. EP N°2 La Pintana | B17: 10194000 | D17: 224. EP N°5 Ciclovia Colina | E17: 595514
D18: 225. EP N°3 El Zorro | E18: 515970
D19: 223. EP N°3 SMAPA | E19: 1200000
D20: 226. EP N°2 IMIV Acceso CV Trading | E20: 2579850
D21: 226. EP N°3 IMIV Acceso CV Trading | E21: 515970
D22: 227. EP N° 1 Y N°2 Vuelo Dron | E22: 2071290
D23: 227. EP N°3 Vuelo Dron | E23: 1115310
A30: TOTAL NO FACTURADO | B30: =+SUM(B3:B17) -> 217324981 | D30: TOTAL NO FACTURADO | E30: =+SUM(E3:E26) -> 32982310 | G30: TOTAL | H30: =+SUM(H3:H29) -> 24729067 | J30: TOTAL | K30: =+SUM(K3:K29) -> 11438356 | M30: TOTAL | N30: =+SUM(N3:N29) -> 8946267 | P30: TOTAL | Q30: =+SUM(Q3:Q13) -> 38644475 | S30: TOTAL | T30: =+SUM(T3:T13) -> 28121678
A32: PÚBLICOS PROXIMOS A FACTURAR/ NO PROYECTADOS | D32: PRIVADOS PRÓXIMOS A FACTURAR/ NO PROYECTADOS
A33: PROYECTO | B33: MONTO A RECIBIR | G33: META FACTURADA | H33: 19300000 | J33: META FACTURADA | K33: =+K30 -> 11438356 | M33: META FACTURADA | N33: =+N30 -> 8946267 | P33: META FACTURADA | Q33: =+Q30 -> 38644475 | S33: META FACTURADA | T33: =+T30 -> 28121678
A34: 009. EP N°2 Aprobación LC | B34: 6896218
A35: 009. EP N°3 Entrega Antecedentes LC | B35: 1379244
A36: 063. EP Parcializado Osorno | B36: 4651788
A37: 212. EP N°2 Machalí ( 50% Ingreso SERVIU) | B37: 20517358 | G37: INGRESO RECIBIDO ENERO 2026 | J37: INGRESO RECIBIDO FEBRERO 2026 | M37: INGRESO RECIBIDO MARZO 2026 | P37: INGRESO RECIBIDO ABRIL 2026 | S37: INGRESO RECIBIDO MAYO 2026
G38: PROYECTO | H38: MONTO RECIBIDO | J38: PROYECTO | K38: MONTO RECIBIDO | M38: PROYECTO | N38: MONTO RECIBIDO | P38: PROYECTO | Q38: MONTO RECIBIDO | S38: PROYECTO | T38: MONTO RECIBIDO
G39: 189. Monografías R5 | H39: 3250000 | J39: 222. EP N°1 Veredas Ochagavia Talagante | K39: =3780000*0.4 -> 1512000 | M39: 224. EP N°2 Ciclovia Colina | N39: 2382300 | P39: 225. EP N°2 El Zorro Lo Barnechea | Q39: 2589711 | S39: 221. EP N°1 La Pintana | T39: 6796000
G40: 189. Monografías R5 | H40: 3614124 | J40: 225. EP N°1 El Zorro Lo Barnechea | K40: 2064182 | M40: 223. EP N°1 Smapa Maipú | N40: 1900000 | P40: 191. EP N°3 Loteo Alvaro Casanova, PÑL | Q40: 2271300 | S40: 212. EP N°2 Machalí ( 50% Ingreso SERVIU) | T40: 20517358
A41: TOTAL NO FACTURADO PERO PROYECTABLE | B41: =+SUM(B34:B39) -> 33444608 | D41: TOTAL NO PAGADO NI FACTURADO | E41: =+E34+E35+E36 -> 0 | G41: 201. Monografías R59-Q | H41: 3750000 | J41: 211. EP N°2 Adicional Holdco | K41: 357239 | M41: 149. EP N°3 Plaza de Armas SFD | N41: 563575 | P41: 191. EP N°3 Señalización Loteo A.Casanova, PÑL | Q41: 1525500 | S41: 210. EP N°2 Triángulo El Tabo | T41: 3250062
G42: 217. Rotura estación central | H42: 555010 | J42: 211. EP N°2 Holdco | K42: 2143435 | M42: 223. EP N°2 Smapa Maipú | N42: 1700000 | P42: 946. EPN° 3 Veredas 18 Septiembre SFD | Q42: 1079200 | S42: 069. EP N°5 G8 y G10, San Antonio | T42: 5093043
G43: 182. UV V5 Conchalí | H43: 357768 | J43: 188. EP N°2 Sendas 7 y 8 Lo Barnechea | K43: 4279875 | M43: 222. EP N°2 Veredas Talagante | N43: 1512000 | P43: 090. EP N°2 Ema Valderrama , LRN | Q43: 1300000 | S43: 227. EP N°1 y 2 Vuelo Dron | T43: 2071290
A44: PÚBLICOS FACTURADOS / NO PROYECTADOS | D44: BOLETAS POR CURSAR | E44: MONTO A RECIBIR | G44: 219. Taller Inofensivo | H44: 595668 | M44: 203. EP N°3 IMIV Melipilla | N44: 637467 | P44: 222. EP N°3 Veredas Talagante | Q44: 756000 | S44: 228. EP N°1 Anticipo ext. | T44: 601404
A45: PROYECTO | B45: MONTO A RECIBIR | G45: 224. Ciclovia San Alfonso | H45: 2382056 | P45: 090. EP N°2 Valenzuela Puelma LRN | Q45: 2600000 | S45: 228. EP N°1 Anticipo int. | T45: 1303042
A46: 090. EP N°2 Parque Tobalaba LRN | B46: 7450000 | P46: 226. EP N°1 IMIV Intermedio CV Trading | Q46: 3187338 | S46: 229. EP N°1 Bodega La Cisterna | T46: 3137690
A47: 057. EP N°4 Circuito Vial, EL Tabo | B47: 5600000 | P47: 210. EP N°1 Triángulo El Tabo | Q47: 3250062
...

Sheet RESUMEN
A1: RESUMEN TRIMESTRAL Q4 · INGENIERÍA
A3: MES | B3: META FACTURADA ($) | C3: FACTURADO REAL ($) | D3: INGRESO CAJA ($) | E3: EFICIENCIA (%)
A4: Enero | B4: ='CURSADO-INGRESADO Q4'!H58 -> 19300000 | C4: ='CURSADO-INGRESADO Q4'!H60 -> 24729067 | D4: ='CURSADO-INGRESADO Q4'!H59 -> 14504626 | E4: =IF(B4>0,C4/B4,0) -> 1.2812988
A5: Febrero | B5: ='CURSADO-INGRESADO Q4'!K58 -> 11438356 | C5: ='CURSADO-INGRESADO Q4'!K60 -> 11438356 | D5: ='CURSADO-INGRESADO Q4'!K59 -> 10356731 | E5: =IF(B5>0,C5/B5,0) -> 1
A6: Marzo | B6: ='CURSADO-INGRESADO Q4'!N58 -> 8946267 | C6: ='CURSADO-INGRESADO Q4'!N60 -> 8946267 | D6: ='CURSADO-INGRESADO Q4'!N59 -> 8695342 | E6: =IF(B6>0,C6/B6,0) -> 1
A7: Abril | B7: ='CURSADO-INGRESADO Q4'!Q58 -> #REF! | C7: ='CURSADO-INGRESADO Q4'!Q60 -> 38644475 | D7: ='CURSADO-INGRESADO Q4'!Q59 -> 30554311 | E7: =IF(B7>0,C7/B7,0) -> #REF!
A8: Mayo | B8: 0 | C8: 0 | D8: 0 | E8: 0
A9: Junio | B9: 0 | C9: 0 | D9: 0 | E9: 0
A10: TOTAL Q4 | B10: =SUM(B4:B9) -> #REF! | C10: =SUM(C4:C9) -> 83758165 | D10: =SUM(D4:D9) -> 64111010 | E10: =IF(B10>0,C10/B10,0) -> #REF!
A12: CUENTAS POR COBRAR · PENDIENTES
A13: CONCEPTO | B13: MONTO ($)
A14: Total NO Facturado (Pendiente pública) | B14: ='CURSADO-INGRESADO Q4'!B29 -> 0
A15: Total Facturado / NO Cobrado | B15: ='CURSADO-INGRESADO Q4'!E29 -> 0
A16: Boletas por Cursar | B16: ='CURSADO-INGRESADO Q4'!E48 -> 0
A17: Próximos a Facturar (no proyect.) | B17: ='CURSADO-INGRESADO Q4'!E41 -> 0

Sheet Hoja1
B8: equipo proyectos | C8: =2600000+2238354+1149309+1724196+1625571 -> 9337430
B9: gaby/fernanda/hugo 50% | C9: =16337579-C8 -> 7000149
B11: Total | C11: 16337579 | E11: 100
C12: 7000149
C15: 0.43
C17: =+C8+850000+600000+2700000 -> 13487430
